Run python scripts/analyze_and_update.py \
  
Traceback (most recent call last):
  File "/home/runner/work/file-record-analyze-automation/file-record-analyze-automation/scripts/analyze_and_update.py", line 15, in <module>
    LOG_DIR.mkdir(parents=True, exist_ok=True)
  File "/opt/hostedtoolcache/Python/3.11.13/x64/lib/python3.11/pathlib.py", line 1116, in mkdir
    os.mkdir(self, mode)
FileExistsError: [Errno 17] File exists: 'analyze_report'
Error: Process completed with exit code 1.
